# 错误处理

## 元数据

- **概念ID**: 09.01
- **概念名称**: 错误处理 (Error Handling)
- **理论层次**: 第二层：语言特征形式化层
- **相关概念**: 09.02 (Result类型), 09.03 (Option类型), 09.04 (panic处理)
- **难度级别**: 中级

## 形式化定义

使用统一符号系统(RFUSS)的形式化定义：

```math
\text{Error}(E, R) \equiv \forall e \in E. \exists r \in R. \text{Handle}(e) \implies \text{Recover}(e, r)
```

其中：

- $\text{Error}(E, R)$ 表示错误集合 $E$ 和恢复策略集合 $R$
- $\forall e \in E$ 表示对所有错误 $e$ 在错误集合 $E$ 中
- $\exists r \in R$ 表示存在恢复策略 $r$ 在恢复策略集合 $R$ 中
- $\text{Handle}(e)$ 表示处理错误 $e$
- $\text{Recover}(e, r)$ 表示使用策略 $r$ 从错误 $e$ 中恢复

## 代码映射

形式化表示与代码的对应关系：

| 形式化表示 | Rust代码 | 说明 |
|----------|---------|------|
| `Error(E, R)` | `Result<T, E>` | 错误处理类型 |
| `∀e ∈ E` | `match error` | 处理所有错误 |
| `∃r ∈ R` | `map_err` | 错误转换策略 |
| `Handle(e)` | `?` 操作符 | 错误传播 |
| `Recover(e, r)` | `unwrap_or` | 错误恢复 |

## 基础示例

最小化示例代码，展示错误处理的核心概念：

```rust
use std::fs::File;
use std::io::{self, Read};

// 基本错误处理
fn divide(a: i32, b: i32) -> Result<i32, &'static str> {
    if b == 0 {
        Err("除数不能为零")
    } else {
        Ok(a / b)
    }
}

// 使用Result类型
fn read_file(path: &str) -> Result<String, io::Error> {
    let mut file = File::open(path)?;
    let mut contents = String::new();
    file.read_to_string(&mut contents)?;
    Ok(contents)
}

// Option类型处理
fn find_element<T: PartialEq>(list: &[T], target: &T) -> Option<usize> {
    for (index, item) in list.iter().enumerate() {
        if item == target {
            return Some(index);
        }
    }
    None
}

fn main() {
    // 基本错误处理
    match divide(10, 2) {
        Ok(result) => println!("除法结果: {}", result),
        Err(e) => println!("错误: {}", e),
    }
    
    match divide(10, 0) {
        Ok(result) => println!("除法结果: {}", result),
        Err(e) => println!("错误: {}", e),
    }
    
    // 使用?操作符
    let result = read_file("example.txt");
    match result {
        Ok(contents) => println!("文件内容: {}", contents),
        Err(e) => println!("读取文件错误: {}", e),
    }
    
    // Option类型使用
    let numbers = vec![1, 2, 3, 4, 5];
    match find_element(&numbers, &3) {
        Some(index) => println!("找到元素在索引: {}", index),
        None => println!("未找到元素"),
    }
    
    match find_element(&numbers, &10) {
        Some(index) => println!("找到元素在索引: {}", index),
        None => println!("未找到元素"),
    }
}
```

**解释**：

- `Result<T, E>` 表示可能成功返回类型T或失败返回错误E
- `?` 操作符自动传播错误
- `Option<T>` 表示可能包含值T或为空
- `match` 语句处理所有可能的情况

## 进阶示例

在实际场景中应用错误处理概念：

```rust
use std::collections::HashMap;
use std::fmt;

// 自定义错误类型
#[derive(Debug)]
enum ValidationError {
    TooShort(String),
    TooLong(String),
    InvalidCharacter(char),
    Empty,
}

impl fmt::Display for ValidationError {
    fn fmt(&self, f: &mut fmt::Formatter) -> fmt::Result {
        match self {
            ValidationError::TooShort(msg) => write!(f, "太短: {}", msg),
            ValidationError::TooLong(msg) => write!(f, "太长: {}", msg),
            ValidationError::InvalidCharacter(c) => write!(f, "无效字符: {}", c),
            ValidationError::Empty => write!(f, "不能为空"),
        }
    }
}

// 验证函数
fn validate_username(username: &str) -> Result<String, ValidationError> {
    if username.is_empty() {
        return Err(ValidationError::Empty);
    }
    
    if username.len() < 3 {
        return Err(ValidationError::TooShort("用户名至少需要3个字符".to_string()));
    }
    
    if username.len() > 20 {
        return Err(ValidationError::TooLong("用户名不能超过20个字符".to_string()));
    }
    
    for c in username.chars() {
        if !c.is_alphanumeric() && c != '_' {
            return Err(ValidationError::InvalidCharacter(c));
        }
    }
    
    Ok(username.to_string())
}

// 错误转换
fn process_user_input(input: &str) -> Result<String, String> {
    validate_username(input)
        .map_err(|e| format!("验证失败: {}", e))
}

// 组合错误处理
struct UserManager {
    users: HashMap<String, String>,
}

impl UserManager {
    fn new() -> Self {
        UserManager {
            users: HashMap::new(),
        }
    }
    
    fn add_user(&mut self, username: &str, email: &str) -> Result<(), String> {
        // 验证用户名
        let valid_username = validate_username(username)?;
        
        // 验证邮箱
        if !email.contains('@') {
            return Err("无效的邮箱格式".to_string());
        }
        
        // 检查用户名是否已存在
        if self.users.contains_key(&valid_username) {
            return Err("用户名已存在".to_string());
        }
        
        self.users.insert(valid_username, email.to_string());
        Ok(())
    }
    
    fn get_user(&self, username: &str) -> Option<&String> {
        self.users.get(username)
    }
    
    fn remove_user(&mut self, username: &str) -> Result<String, String> {
        self.users.remove(username)
            .ok_or_else(|| "用户不存在".to_string())
    }
}

// 错误恢复策略
fn safe_divide(a: f64, b: f64) -> Result<f64, &'static str> {
    if b == 0.0 {
        Err("除数不能为零")
    } else {
        Ok(a / b)
    }
}

fn calculate_average(numbers: &[f64]) -> f64 {
    if numbers.is_empty() {
        return 0.0; // 默认值
    }
    
    let sum: f64 = numbers.iter().sum();
    sum / numbers.len() as f64
}

fn main() {
    let mut user_manager = UserManager::new();
    
    // 测试用户添加
    let test_cases = vec![
        ("john_doe", "john@example.com"),
        ("", "invalid@example.com"), // 空用户名
        ("ab", "short@example.com"), // 太短
        ("very_long_username_that_exceeds_limit", "long@example.com"), // 太长
        ("user@name", "special@example.com"), // 特殊字符
        ("john_doe", "duplicate@example.com"), // 重复用户名
    ];
    
    for (username, email) in test_cases {
        match user_manager.add_user(username, email) {
            Ok(_) => println!("✅ 成功添加用户: {}", username),
            Err(e) => println!("❌ 添加用户失败: {} - {}", username, e),
        }
    }
    
    // 测试用户查询
    let usernames = vec!["john_doe", "nonexistent"];
    for username in usernames {
        match user_manager.get_user(username) {
            Some(email) => println!("📧 用户 {} 的邮箱: {}", username, email),
            None => println!("❓ 用户 {} 不存在", username),
        }
    }
    
    // 测试用户删除
    match user_manager.remove_user("john_doe") {
        Ok(email) => println!("🗑️  删除用户成功，邮箱: {}", email),
        Err(e) => println!("❌ 删除用户失败: {}", e),
    }
    
    // 错误恢复示例
    let numbers = vec![1.0, 2.0, 3.0, 4.0, 5.0];
    let average = calculate_average(&numbers);
    println!("📊 平均值: {}", average);
    
    let empty_numbers: Vec<f64> = vec![];
    let empty_average = calculate_average(&empty_numbers);
    println!("📊 空列表平均值: {}", empty_average);
    
    // 使用unwrap_or提供默认值
    let result = safe_divide(10.0, 0.0);
    let value = result.unwrap_or(0.0);
    println!("🔢 安全除法结果: {}", value);
}
```

**解释**：

- 自定义错误类型提供更精确的错误信息
- 错误转换使用 `map_err` 和 `?` 操作符
- 组合错误处理处理多个可能的错误来源
- 错误恢复策略提供默认值和替代方案

## 边界情况

展示错误处理的边界条件和复杂情况：

```rust
use std::panic::{catch_unwind, AssertUnwindSafe};
use std::sync::{Arc, Mutex};
use std::thread;

// panic处理
fn safe_operation<F, T>(operation: F) -> Result<T, String>
where
    F: FnOnce() -> T + AssertUnwindSafe,
{
    catch_unwind(operation)
        .map_err(|e| format!("操作失败: {:?}", e))
}

// 递归错误处理
fn recursive_operation(n: u32) -> Result<u32, String> {
    if n == 0 {
        return Ok(0);
    }
    
    if n > 1000 {
        return Err("递归深度过大".to_string());
    }
    
    let prev = recursive_operation(n - 1)?;
    Ok(prev + n)
}

// 异步错误处理
async fn async_operation() -> Result<String, String> {
    // 模拟异步操作
    tokio::time::sleep(std::time::Duration::from_millis(100)).await;
    
    // 模拟随机错误
    if rand::random::<bool>() {
        Ok("异步操作成功".to_string())
    } else {
        Err("异步操作失败".to_string())
    }
}

// 错误传播链
fn operation_chain() -> Result<String, String> {
    let step1 = perform_step1()?;
    let step2 = perform_step2(&step1)?;
    let step3 = perform_step3(&step2)?;
    Ok(step3)
}

fn perform_step1() -> Result<String, String> {
    Ok("步骤1完成".to_string())
}

fn perform_step2(input: &str) -> Result<String, String> {
    if input.contains("错误") {
        Err("步骤2失败".to_string())
    } else {
        Ok(format!("步骤2处理: {}", input))
    }
}

fn perform_step3(input: &str) -> Result<String, String> {
    Ok(format!("最终结果: {}", input))
}

// 错误聚合
#[derive(Debug)]
struct ValidationResult {
    errors: Vec<String>,
    warnings: Vec<String>,
}

impl ValidationResult {
    fn new() -> Self {
        ValidationResult {
            errors: Vec::new(),
            warnings: Vec::new(),
        }
    }
    
    fn add_error(&mut self, error: String) {
        self.errors.push(error);
    }
    
    fn add_warning(&mut self, warning: String) {
        self.warnings.push(warning);
    }
    
    fn is_valid(&self) -> bool {
        self.errors.is_empty()
    }
    
    fn has_warnings(&self) -> bool {
        !self.warnings.is_empty()
    }
}

fn validate_complex_data(data: &str) -> ValidationResult {
    let mut result = ValidationResult::new();
    
    // 检查长度
    if data.len() < 5 {
        result.add_error("数据太短".to_string());
    } else if data.len() > 100 {
        result.add_warning("数据较长".to_string());
    }
    
    // 检查字符
    if !data.chars().all(|c| c.is_alphanumeric()) {
        result.add_error("包含非字母数字字符".to_string());
    }
    
    // 检查特定模式
    if data.contains("test") {
        result.add_warning("包含测试数据".to_string());
    }
    
    result
}

// 线程安全错误处理
struct ThreadSafeCounter {
    count: Arc<Mutex<u32>>,
}

impl ThreadSafeCounter {
    fn new() -> Self {
        ThreadSafeCounter {
            count: Arc::new(Mutex::new(0)),
        }
    }
    
    fn increment(&self) -> Result<u32, String> {
        let mut count = self.count.lock()
            .map_err(|_| "无法获取锁".to_string())?;
        
        *count += 1;
        Ok(*count)
    }
    
    fn get_count(&self) -> Result<u32, String> {
        let count = self.count.lock()
            .map_err(|_| "无法获取锁".to_string())?;
        
        Ok(*count)
    }
}

fn main() {
    // panic处理测试
    let result = safe_operation(|| {
        // 模拟可能panic的操作
        let x = 10;
        let y = 0;
        x / y // 这会panic
    });
    
    match result {
        Ok(value) => println!("操作成功: {}", value),
        Err(e) => println!("操作失败: {}", e),
    }
    
    // 递归错误处理
    match recursive_operation(5) {
        Ok(result) => println!("递归结果: {}", result),
        Err(e) => println!("递归错误: {}", e),
    }
    
    // 错误传播链
    match operation_chain() {
        Ok(result) => println!("操作链结果: {}", result),
        Err(e) => println!("操作链错误: {}", e),
    }
    
    // 复杂验证
    let test_data = vec![
        "short",
        "very_long_data_that_exceeds_normal_length_and_contains_test_pattern",
        "normal123",
        "invalid@data",
    ];
    
    for data in test_data {
        let validation = validate_complex_data(data);
        println!("验证 '{}':", data);
        
        if validation.is_valid() {
            println!("  ✅ 验证通过");
        } else {
            println!("  ❌ 验证失败");
            for error in &validation.errors {
                println!("    错误: {}", error);
            }
        }
        
        if validation.has_warnings() {
            for warning in &validation.warnings {
                println!("    ⚠️  警告: {}", warning);
            }
        }
        println!();
    }
    
    // 线程安全错误处理
    let counter = ThreadSafeCounter::new();
    let counter_clone = counter.clone();
    
    let handle = thread::spawn(move || {
        for _ in 0..5 {
            match counter_clone.increment() {
                Ok(count) => println!("线程中计数: {}", count),
                Err(e) => println!("线程中错误: {}", e),
            }
        }
    });
    
    handle.join().unwrap();
    
    match counter.get_count() {
        Ok(count) => println!("最终计数: {}", count),
        Err(e) => println!("获取计数错误: {}", e),
    }
}

// 为ThreadSafeCounter实现Clone
impl Clone for ThreadSafeCounter {
    fn clone(&self) -> Self {
        ThreadSafeCounter {
            count: Arc::clone(&self.count),
        }
    }
}
```

**解释**：

- panic处理使用 `catch_unwind` 捕获panic
- 递归错误处理需要深度限制
- 异步错误处理使用 `?` 操作符
- 错误传播链展示错误在函数间的传递
- 错误聚合收集多个错误和警告
- 线程安全错误处理处理并发场景

## 常见错误

展示与错误处理相关的常见错误及修正：

```rust
fn main() {
    // 错误1: 忽略错误
    // let file = File::open("nonexistent.txt").unwrap(); // 错误：可能panic
    
    // 错误2: 不完整的错误处理
    // fn bad_function() -> Result<String, String> {
    //     let file = File::open("file.txt")?; // 错误：类型不匹配
    //     Ok("success".to_string())
    // }
    
    // 错误3: 错误的错误传播
    // fn wrong_propagation() -> Result<String, String> {
    //     let result: Result<String, io::Error> = read_file("file.txt");
    //     result // 错误：类型不匹配
    // }
    
    // 错误4: 忽略Option
    // let value = Some(42);
    // let result = value.unwrap(); // 错误：如果为None会panic
}
```

**错误原因**：

- 忽略错误：使用 `unwrap()` 可能导致panic
- 不完整的错误处理：错误类型不匹配
- 错误的错误传播：返回类型不匹配
- 忽略Option：没有检查None情况

**正确版本**：

```rust
use std::fs::File;
use std::io;

fn main() {
    // 修正1: 正确处理错误
    match File::open("nonexistent.txt") {
        Ok(file) => println!("文件打开成功"),
        Err(e) => println!("文件打开失败: {}", e),
    }
    
    // 修正2: 正确的错误类型
    fn good_function() -> Result<String, String> {
        let file = File::open("file.txt")
            .map_err(|e| format!("文件错误: {}", e))?;
        Ok("success".to_string())
    }
    
    // 修正3: 正确的错误传播
    fn correct_propagation() -> Result<String, String> {
        let result: Result<String, io::Error> = read_file("file.txt");
        result.map_err(|e| format!("IO错误: {}", e))
    }
    
    // 修正4: 正确处理Option
    let value = Some(42);
    match value {
        Some(v) => println!("值: {}", v),
        None => println!("没有值"),
    }
    
    // 或者使用安全的方法
    let result = value.unwrap_or(0);
    println!("安全值: {}", result);
}

fn read_file(path: &str) -> Result<String, io::Error> {
    let mut file = File::open(path)?;
    let mut contents = String::new();
    file.read_to_string(&mut contents)?;
    Ok(contents)
}
```

## 性能考量

讨论错误处理的性能特征：

- **零成本抽象**：Result和Option在运行时没有额外开销
- **错误传播开销**：`?` 操作符有少量开销
- **错误类型大小**：错误类型影响Result的大小
- **错误处理分支**：错误处理路径可能影响性能
- **错误聚合开销**：收集多个错误有内存开销

## 最佳实践

提供使用错误处理的最佳实践建议：

1. **使用Result而不是panic**：在库代码中避免panic
2. **提供有意义的错误信息**：错误信息应该帮助调试
3. **使用自定义错误类型**：为特定领域定义错误类型
4. **正确处理Option**：使用match或安全的方法
5. **避免unwrap**：在生产代码中避免使用unwrap
6. **使用错误转换**：使用map_err转换错误类型
7. **聚合错误**：收集多个错误而不是只报告第一个
8. **测试错误路径**：编写测试验证错误处理

## 相关资源

- [Rust错误处理](https://doc.rust-lang.org/book/ch09-00-error-handling.html)
- [Result类型](https://doc.rust-lang.org/std/result/)
- [Option类型](https://doc.rust-lang.org/std/option/)
- [thiserror库](https://docs.rs/thiserror/)
- [anyhow库](https://docs.rs/anyhow/)

"

---
