# 错误处理语义分析


## 📊 目录

- [概述](#概述)
- [1. 错误处理理论基础](#1-错误处理理论基础)
  - [1.1 错误处理概念](#11-错误处理概念)
  - [1.2 Rust错误处理哲学](#12-rust错误处理哲学)
- [2. Result类型语义](#2-result类型语义)
  - [2.1 Result类型定义](#21-result类型定义)
  - [2.2 Result类型方法](#22-result类型方法)
- [3. Option类型语义](#3-option类型语义)
  - [3.1 Option类型定义](#31-option类型定义)
  - [3.2 Option类型方法](#32-option类型方法)
- [4. 错误传播](#4-错误传播)
  - [4.1 ?操作符](#41-操作符)
  - [4.2 错误转换](#42-错误转换)
- [5. 异常安全](#5-异常安全)
  - [5.1 异常安全保证](#51-异常安全保证)
  - [5.2 异常安全模式](#52-异常安全模式)
- [6. 错误恢复机制](#6-错误恢复机制)
  - [6.1 错误恢复策略](#61-错误恢复策略)
  - [6.2 错误监控和日志](#62-错误监控和日志)
- [7. 错误处理模式](#7-错误处理模式)
  - [7.1 常见错误处理模式](#71-常见错误处理模式)
  - [7.2 错误处理最佳实践](#72-错误处理最佳实践)
- [8. 测试和验证](#8-测试和验证)
  - [8.1 错误处理测试](#81-错误处理测试)
- [9. 总结](#9-总结)


## 概述

本文档详细分析Rust错误处理系统的语义，包括Result类型、Option类型、错误传播、异常安全、错误恢复机制和错误处理模式。

## 1. 错误处理理论基础

### 1.1 错误处理概念

**定义 1.1.1 (错误处理)**
错误处理是指程序在遇到异常情况时能够优雅地处理并恢复的能力，包括错误检测、错误传播、错误恢复和错误报告。

**错误处理的分类**：

1. **可恢复错误**：程序可以从中恢复并继续执行的错误
2. **不可恢复错误**：程序无法从中恢复，需要终止执行的错误
3. **预期错误**：程序设计中预期的错误情况
4. **意外错误**：程序设计中未预期的错误情况

### 1.2 Rust错误处理哲学

**Rust错误处理原则**：

```rust
// Rust鼓励显式错误处理，避免隐式错误传播
fn divide(a: i32, b: i32) -> Result<i32, String> {
    if b == 0 {
        Err("Division by zero".to_string())
    } else {
        Ok(a / b)
    }
}

// 使用Result类型强制处理错误
fn main() {
    match divide(10, 0) {
        Ok(result) => println!("Result: {}", result),
        Err(e) => println!("Error: {}", e),
    }
}
```

## 2. Result类型语义

### 2.1 Result类型定义

**Result类型语义**：

```rust
// Result类型定义
enum Result<T, E> {
    Ok(T),   // 成功值
    Err(E),  // 错误值
}

// Result类型的基本操作
fn result_basic_operations() {
    // 创建成功结果
    let success: Result<i32, String> = Ok(42);
    
    // 创建错误结果
    let error: Result<i32, String> = Err("Something went wrong".to_string());
    
    // 模式匹配
    match success {
        Ok(value) => println!("Success: {}", value),
        Err(e) => println!("Error: {}", e),
    }
    
    // 使用unwrap（不推荐在生产代码中使用）
    let value = success.unwrap(); // 42
    // let value = error.unwrap(); // 会panic!
    
    // 使用unwrap_or提供默认值
    let value = error.unwrap_or(0); // 0
    
    // 使用map转换成功值
    let doubled = success.map(|x| x * 2); // Ok(84)
    
    // 使用map_err转换错误值
    let error_with_prefix = error.map_err(|e| format!("Error: {}", e));
}
```

### 2.2 Result类型方法

**Result类型的方法语义**：

```rust
fn result_methods() {
    let success: Result<i32, String> = Ok(42);
    let error: Result<i32, String> = Err("Error".to_string());
    
    // is_ok和is_err
    assert!(success.is_ok());
    assert!(error.is_err());
    
    // ok和err方法
    assert_eq!(success.ok(), Some(42));
    assert_eq!(success.err(), None);
    assert_eq!(error.ok(), None);
    assert_eq!(error.err(), Some("Error".to_string()));
    
    // as_ref和as_mut
    let success_ref = success.as_ref(); // Result<&i32, &String>
    let success_mut = success.as_mut(); // Result<&mut i32, &mut String>
    
    // map系列方法
    let doubled = success.map(|x| x * 2); // Ok(84)
    let error_msg = error.map_err(|e| format!("Custom: {}", e)); // Err("Custom: Error")
    
    // and_then和or_else
    let chained = success.and_then(|x| {
        if x > 0 {
            Ok(x * 2)
        } else {
            Err("Negative number".to_string())
        }
    }); // Ok(84)
    
    let recovered = error.or_else(|_| Ok(0)); // Ok(0)
}
```

## 3. Option类型语义

### 3.1 Option类型定义

**Option类型语义**：

```rust
// Option类型定义
enum Option<T> {
    Some(T), // 有值
    None,    // 无值
}

// Option类型的基本操作
fn option_basic_operations() {
    // 创建Some值
    let some_value: Option<i32> = Some(42);
    
    // 创建None值
    let none_value: Option<i32> = None;
    
    // 模式匹配
    match some_value {
        Some(value) => println!("Value: {}", value),
        None => println!("No value"),
    }
    
    // 使用unwrap
    let value = some_value.unwrap(); // 42
    // let value = none_value.unwrap(); // 会panic!
    
    // 使用unwrap_or提供默认值
    let value = none_value.unwrap_or(0); // 0
    
    // 使用map转换值
    let doubled = some_value.map(|x| x * 2); // Some(84)
    let doubled_none = none_value.map(|x| x * 2); // None
}
```

### 3.2 Option类型方法

**Option类型的方法语义**：

```rust
fn option_methods() {
    let some_value: Option<i32> = Some(42);
    let none_value: Option<i32> = None;
    
    // is_some和is_none
    assert!(some_value.is_some());
    assert!(none_value.is_none());
    
    // as_ref和as_mut
    let some_ref = some_value.as_ref(); // Option<&i32>
    let some_mut = some_value.as_mut(); // Option<&mut i32>
    
    // map系列方法
    let doubled = some_value.map(|x| x * 2); // Some(84)
    let doubled_none = none_value.map(|x| x * 2); // None
    
    // and_then和or_else
    let chained = some_value.and_then(|x| {
        if x > 0 {
            Some(x * 2)
        } else {
            None
        }
    }); // Some(84)
    
    let recovered = none_value.or_else(|| Some(0)); // Some(0)
    
    // filter方法
    let filtered = some_value.filter(|&x| x > 40); // Some(42)
    let filtered_none = some_value.filter(|&x| x > 50); // None
    
    // take和replace
    let mut value = Some(42);
    let taken = value.take(); // Some(42), value变为None
    value.replace(100); // value变为Some(100)
}
```

## 4. 错误传播

### 4.1 ?操作符

**错误传播语义**：

```rust
use std::fs::File;
use std::io::{self, Read};

// 使用?操作符传播错误
fn read_file_contents(filename: &str) -> Result<String, io::Error> {
    let mut file = File::open(filename)?; // 如果失败，立即返回错误
    let mut contents = String::new();
    file.read_to_string(&mut contents)?; // 如果失败，立即返回错误
    Ok(contents)
}

// 链式错误传播
fn process_file(filename: &str) -> Result<String, io::Error> {
    let contents = read_file_contents(filename)?;
    Ok(contents.to_uppercase())
}

// 在Option中使用?
fn find_user(id: u32) -> Option<User> {
    let user = get_user_from_db(id)?; // 如果返回None，立即返回None
    Some(user)
}

// 自定义错误类型
#[derive(Debug)]
enum AppError {
    Io(io::Error),
    Parse(String),
    NotFound,
}

impl From<io::Error> for AppError {
    fn from(err: io::Error) -> Self {
        AppError::Io(err)
    }
}

// 使用自定义错误类型
fn process_with_custom_error(filename: &str) -> Result<String, AppError> {
    let contents = read_file_contents(filename)?; // io::Error自动转换为AppError
    Ok(contents)
}
```

### 4.2 错误转换

**错误转换语义**：

```rust
use std::fmt;

// 错误转换trait
trait Error: fmt::Debug + fmt::Display {
    fn source(&self) -> Option<&(dyn Error + 'static)> { None }
}

// 实现From trait进行错误转换
impl From<std::io::Error> for AppError {
    fn from(err: std::io::Error) -> Self {
        AppError::Io(err)
    }
}

impl From<std::num::ParseIntError> for AppError {
    fn from(err: std::num::ParseIntError) -> Self {
        AppError::Parse(err.to_string())
    }
}

// 使用map_err进行显式错误转换
fn parse_number(s: &str) -> Result<i32, AppError> {
    s.parse::<i32>()
        .map_err(|e| AppError::Parse(e.to_string()))
}

// 使用?操作符自动转换
fn parse_and_process(s: &str) -> Result<i32, AppError> {
    let num = s.parse::<i32>()?; // 自动转换为AppError
    Ok(num * 2)
}
```

## 5. 异常安全

### 5.1 异常安全保证

**异常安全语义**：

```rust
use std::panic;

// Rust的异常安全保证
fn exception_safety_example() {
    // 设置panic hook
    panic::set_hook(Box::new(|panic_info| {
        println!("Panic occurred: {:?}", panic_info);
    }));
    
    // 使用catch_unwind捕获panic
    let result = panic::catch_unwind(|| {
        // 可能panic的代码
        if true {
            panic!("Intentional panic");
        }
    });
    
    match result {
        Ok(_) => println!("No panic occurred"),
        Err(_) => println!("Panic was caught"),
    }
}

// 资源管理保证
struct Resource {
    data: Vec<i32>,
}

impl Resource {
    fn new() -> Self {
        Self { data: Vec::new() }
    }
    
    fn add_data(&mut self, value: i32) {
        self.data.push(value);
    }
}

impl Drop for Resource {
    fn drop(&mut self) {
        println!("Resource being dropped with data: {:?}", self.data);
    }
}

// 即使发生panic，资源也会被正确清理
fn resource_management() {
    let mut resource = Resource::new();
    resource.add_data(1);
    resource.add_data(2);
    
    // 即使这里panic，resource的drop也会被调用
    // panic!("This will not prevent resource cleanup");
}
```

### 5.2 异常安全模式

**异常安全模式实现**：

```rust
// RAII模式（Resource Acquisition Is Initialization）
struct FileHandle {
    file: Option<std::fs::File>,
}

impl FileHandle {
    fn new(filename: &str) -> Result<Self, std::io::Error> {
        let file = std::fs::File::open(filename)?;
        Ok(Self { file: Some(file) })
    }
    
    fn read(&mut self) -> Result<String, std::io::Error> {
        let mut contents = String::new();
        if let Some(ref mut file) = self.file {
            file.read_to_string(&mut contents)?;
        }
        Ok(contents)
    }
}

impl Drop for FileHandle {
    fn drop(&mut self) {
        // 文件会在作用域结束时自动关闭
        println!("File handle dropped");
    }
}

// 事务模式
struct Transaction {
    operations: Vec<Box<dyn FnOnce() -> Result<(), String>>>,
}

impl Transaction {
    fn new() -> Self {
        Self { operations: Vec::new() }
    }
    
    fn add_operation<F>(&mut self, operation: F)
    where
        F: FnOnce() -> Result<(), String> + 'static,
    {
        self.operations.push(Box::new(operation));
    }
    
    fn execute(self) -> Result<(), String> {
        let mut executed = Vec::new();
        
        for operation in self.operations {
            match operation() {
                Ok(()) => executed.push(operation),
                Err(e) => {
                    // 回滚已执行的操作
                    for rollback_op in executed.into_iter().rev() {
                        // 这里应该执行回滚操作
                        println!("Rolling back operation");
                    }
                    return Err(e);
                }
            }
        }
        
        Ok(())
    }
}
```

## 6. 错误恢复机制

### 6.1 错误恢复策略

**错误恢复语义**：

```rust
// 重试机制
fn retry_operation<F, T, E>(mut operation: F, max_retries: usize) -> Result<T, E>
where
    F: FnMut() -> Result<T, E>,
    E: std::fmt::Debug,
{
    let mut last_error = None;
    
    for attempt in 0..=max_retries {
        match operation() {
            Ok(result) => return Ok(result),
            Err(e) => {
                last_error = Some(e);
                if attempt < max_retries {
                    println!("Attempt {} failed, retrying...", attempt + 1);
                    std::thread::sleep(std::time::Duration::from_millis(100 * (attempt + 1) as u64));
                }
            }
        }
    }
    
    Err(last_error.unwrap())
}

// 使用重试机制
fn example_retry() {
    let result = retry_operation(
        || {
            // 模拟可能失败的操作
            if rand::random::<bool>() {
                Ok("Success")
            } else {
                Err("Temporary failure")
            }
        },
        3,
    );
    
    match result {
        Ok(value) => println!("Succeeded: {}", value),
        Err(e) => println!("Failed after retries: {:?}", e),
    }
}

// 降级机制
enum ServiceResponse {
    FullResponse(String),
    CachedResponse(String),
    ErrorResponse(String),
}

fn service_with_fallback() -> ServiceResponse {
    // 尝试主服务
    match call_primary_service() {
        Ok(response) => ServiceResponse::FullResponse(response),
        Err(_) => {
            // 主服务失败，尝试缓存
            match get_cached_response() {
                Ok(cached) => ServiceResponse::CachedResponse(cached),
                Err(_) => ServiceResponse::ErrorResponse("Service unavailable".to_string()),
            }
        }
    }
}

fn call_primary_service() -> Result<String, String> {
    // 模拟主服务调用
    Err("Primary service down".to_string())
}

fn get_cached_response() -> Result<String, String> {
    // 模拟缓存获取
    Ok("Cached data".to_string())
}
```

### 6.2 错误监控和日志

**错误监控语义**：

```rust
use std::sync::{Arc, Mutex};
use std::collections::HashMap;

// 错误监控器
struct ErrorMonitor {
    error_counts: Arc<Mutex<HashMap<String, usize>>>,
}

impl ErrorMonitor {
    fn new() -> Self {
        Self {
            error_counts: Arc::new(Mutex::new(HashMap::new())),
        }
    }
    
    fn record_error(&self, error_type: &str) {
        let mut counts = self.error_counts.lock().unwrap();
        *counts.entry(error_type.to_string()).or_insert(0) += 1;
    }
    
    fn get_error_stats(&self) -> HashMap<String, usize> {
        self.error_counts.lock().unwrap().clone()
    }
}

// 错误日志记录
struct ErrorLogger {
    monitor: ErrorMonitor,
}

impl ErrorLogger {
    fn new() -> Self {
        Self {
            monitor: ErrorMonitor::new(),
        }
    }
    
    fn log_error<T, E: std::fmt::Display>(&self, result: Result<T, E>, context: &str) -> Result<T, E> {
        if let Err(ref e) = result {
            println!("Error in {}: {}", context, e);
            self.monitor.record_error(&format!("{}_error", context));
        }
        result
    }
}

// 使用错误监控
fn monitored_operation() {
    let logger = ErrorLogger::new();
    
    let result = logger.log_error(
        risky_operation(),
        "data_processing",
    );
    
    match result {
        Ok(_) => println!("Operation succeeded"),
        Err(_) => {
            let stats = logger.monitor.get_error_stats();
            println!("Error statistics: {:?}", stats);
        }
    }
}

fn risky_operation() -> Result<(), String> {
    // 模拟可能失败的操作
    Err("Operation failed".to_string())
}
```

## 7. 错误处理模式

### 7.1 常见错误处理模式

**错误处理模式实现**：

```rust
// 早期返回模式
fn early_return_pattern(data: &str) -> Result<i32, String> {
    if data.is_empty() {
        return Err("Empty data".to_string());
    }
    
    if !data.chars().all(|c| c.is_digit(10)) {
        return Err("Invalid number format".to_string());
    }
    
    match data.parse::<i32>() {
        Ok(num) => Ok(num),
        Err(_) => Err("Parse error".to_string()),
    }
}

// 错误包装模式
struct WrappedError {
    inner: Box<dyn std::error::Error + Send + Sync>,
    context: String,
}

impl std::fmt::Display for WrappedError {
    fn fmt(&self, f: &mut std::fmt::Formatter<'_>) -> std::fmt::Result {
        write!(f, "{}: {}", self.context, self.inner)
    }
}

impl std::fmt::Debug for WrappedError {
    fn fmt(&self, f: &mut std::fmt::Formatter<'_>) -> std::fmt::Result {
        write!(f, "WrappedError {{ context: {:?}, inner: {:?} }}", self.context, self.inner)
    }
}

impl std::error::Error for WrappedError {
    fn source(&self) -> Option<&(dyn std::error::Error + 'static)> {
        Some(&*self.inner)
    }
}

// 错误组合模式
#[derive(Debug)]
enum CombinedError {
    Io(std::io::Error),
    Parse(std::num::ParseIntError),
    Custom(String),
}

impl From<std::io::Error> for CombinedError {
    fn from(err: std::io::Error) -> Self {
        CombinedError::Io(err)
    }
}

impl From<std::num::ParseIntError> for CombinedError {
    fn from(err: std::num::ParseIntError) -> Self {
        CombinedError::Parse(err)
    }
}

impl std::fmt::Display for CombinedError {
    fn fmt(&self, f: &mut std::fmt::Formatter<'_>) -> std::fmt::Result {
        match self {
            CombinedError::Io(e) => write!(f, "IO error: {}", e),
            CombinedError::Parse(e) => write!(f, "Parse error: {}", e),
            CombinedError::Custom(s) => write!(f, "Custom error: {}", s),
        }
    }
}

impl std::error::Error for CombinedError {}
```

### 7.2 错误处理最佳实践

**错误处理最佳实践**：

```rust
// 1. 使用具体的错误类型
#[derive(Debug, thiserror::Error)]
enum DatabaseError {
    #[error("Connection failed: {0}")]
    Connection(String),
    #[error("Query failed: {0}")]
    Query(String),
    #[error("Transaction failed: {0}")]
    Transaction(String),
}

// 2. 提供有意义的错误信息
fn meaningful_error_handling() -> Result<(), DatabaseError> {
    let connection_result = connect_to_database();
    
    match connection_result {
        Ok(_) => Ok(()),
        Err(e) => Err(DatabaseError::Connection(
            format!("Failed to connect to database: {}", e)
        )),
    }
}

fn connect_to_database() -> Result<(), String> {
    Err("Connection timeout".to_string())
}

// 3. 使用Result类型而不是panic
fn safe_division(a: i32, b: i32) -> Result<i32, String> {
    if b == 0 {
        Err("Division by zero is not allowed".to_string())
    } else {
        Ok(a / b)
    }
}

// 4. 提供错误恢复选项
fn robust_file_processing(filename: &str) -> Result<String, String> {
    // 尝试读取文件
    match std::fs::read_to_string(filename) {
        Ok(contents) => Ok(contents),
        Err(_) => {
            // 尝试读取备份文件
            let backup_filename = format!("{}.backup", filename);
            match std::fs::read_to_string(&backup_filename) {
                Ok(contents) => Ok(contents),
                Err(_) => Err(format!("Failed to read both {} and {}", filename, backup_filename)),
            }
        }
    }
}

// 5. 使用适当的错误传播
fn process_data(data: &str) -> Result<i32, CombinedError> {
    let file_contents = std::fs::read_to_string("config.txt")?; // 自动转换IO错误
    let config_value: i32 = file_contents.trim().parse()?; // 自动转换解析错误
    
    if config_value == 0 {
        return Err(CombinedError::Custom("Invalid configuration".to_string()));
    }
    
    Ok(config_value)
}
```

## 8. 测试和验证

### 8.1 错误处理测试

**错误处理测试框架**：

```rust
#[cfg(test)]
mod tests {
    use super::*;

    #[test]
    fn test_result_basic_operations() {
        let success: Result<i32, String> = Ok(42);
        let error: Result<i32, String> = Err("Error".to_string());
        
        assert!(success.is_ok());
        assert!(error.is_err());
        assert_eq!(success.unwrap(), 42);
        assert_eq!(error.unwrap_or(0), 0);
    }

    #[test]
    fn test_option_basic_operations() {
        let some_value: Option<i32> = Some(42);
        let none_value: Option<i32> = None;
        
        assert!(some_value.is_some());
        assert!(none_value.is_none());
        assert_eq!(some_value.unwrap(), 42);
        assert_eq!(none_value.unwrap_or(0), 0);
    }

    #[test]
    fn test_error_propagation() {
        let result = process_data("test");
        assert!(result.is_err());
    }

    #[test]
    fn test_retry_mechanism() {
        let mut attempts = 0;
        let result = retry_operation(
            || {
                attempts += 1;
                if attempts < 3 {
                    Err("Temporary failure")
                } else {
                    Ok("Success")
                }
            },
            5,
        );
        
        assert!(result.is_ok());
        assert_eq!(attempts, 3);
    }

    #[test]
    fn test_error_monitoring() {
        let monitor = ErrorMonitor::new();
        monitor.record_error("test_error");
        monitor.record_error("test_error");
        
        let stats = monitor.get_error_stats();
        assert_eq!(stats.get("test_error"), Some(&2));
    }

    #[test]
    fn test_early_return_pattern() {
        assert!(early_return_pattern("").is_err());
        assert!(early_return_pattern("abc").is_err());
        assert!(early_return_pattern("123").is_ok());
    }

    #[test]
    fn test_safe_division() {
        assert_eq!(safe_division(10, 2), Ok(5));
        assert!(safe_division(10, 0).is_err());
    }

    #[test]
    fn test_robust_file_processing() {
        // 测试文件不存在的情况
        let result = robust_file_processing("nonexistent.txt");
        assert!(result.is_err());
    }
}
```

## 9. 总结

Rust的错误处理系统通过Result和Option类型提供了强大而安全的错误处理机制。通过显式错误处理、错误传播、异常安全保证和丰富的错误处理模式，Rust程序能够优雅地处理各种错误情况。

错误处理是Rust语言的核心特性之一，它通过编译时检查确保错误得到适当处理，同时提供了灵活的错误恢复和监控机制，为构建健壮的应用程序提供了坚实的基础。
